<mujoco model="space satellite scene">
  <compiler angle="radian" meshdir="assets" />
  <option integrator="implicitfast" gravity="0 0 0" />

  <include file="gen3_7dof_assets.xml" />

  <statistic center="0.3 0 0.4" extent="1" />
  <default>
    <geom solref=".004 1" />
  </default>

  <visual>
    <headlight diffuse="0.6 0.6 0.6" ambient="0.3 0.3 0.3" specular="0 0 0" />
    <rgba haze="0.15 0.25 0.35 1" />
    <global azimuth="120" elevation="-20" offwidth="1920" offheight="1080" />
  </visual>

  <asset>
    <texture
      type="skybox"
      file="assets/space.png"
      gridsize="3 4"
      gridlayout=".U..LFRB.D.."
    />
    <material name="landsat_gold" rgba="1.0 0.85 0.6  1" reflectance="0.2" />
    <material name="metal_rafti" rgba="0.8 0.8 0.8 1" reflectance="0.5" />
    <material
      name="servicer_platform_blue"
      rgba="0.1 0.1 0.7 1"
      reflectance="0.5"
    />
    <material
      name="servicer_platform_gold"
      rgba="0.7 0.6 0.4 1"
      reflectance="0.5"
    />
    <material
      name="servicer_platform_silver"
      rgba="0.6 0.6 0.6 1"
      reflectance="0.5"
    />
    <mesh name="april_tag" file="april_tag.obj" />
    <mesh name="landsat" file="landsat/landsat.obj" />
    <mesh name="landsat_white" file="landsat/landsat_white.obj" />
    <mesh name="landsat_glass" file="landsat/landsat_glass.obj" />
    <mesh name="landsat_collision_1" file="landsat/landsat_collision_1.obj" />
    <mesh name="landsat_collision_2" file="landsat/landsat_collision_2.obj" />
    <mesh name="landsat_collision_3" file="landsat/landsat_collision_3.obj" />
    <mesh name="landsat_collision_4" file="landsat/landsat_collision_4.obj" />
    <mesh name="rafti" file="rafti/rafti.obj" />
    <mesh name="rafti_collision_1" file="rafti/rafti_collision_1.obj" />
    <mesh name="rafti_collision_2" file="rafti/rafti_collision_2.obj" />
    <mesh name="rafti_collision_3" file="rafti/rafti_collision_3.obj" />
    <mesh name="rafti_collision_4" file="rafti/rafti_collision_4.obj" />
    <mesh name="rafti_collision_5" file="rafti/rafti_collision_5.obj" />
    <mesh name="epastar" file="servicer_platform/epastar.obj" />
    <mesh name="interface" file="servicer_platform/interface.obj" />
    <mesh name="rpo_suite" file="servicer_platform/rpo_suite.obj" />
    <mesh name="pole" file="servicer_platform/pole.obj" />
    <mesh name="solar_panels" file="servicer_platform/solar_panels.obj" />
    <mesh
      name="epastar_collision"
      file="servicer_platform/epastar_collision.obj"
    />
    <mesh
      name="interface_collision"
      file="servicer_platform/interface_collision.obj"
    />
    <mesh
      name="rpo_suite_collision"
      file="servicer_platform/rpo_suite_collision.obj"
    />
    <mesh name="pole_collision" file="servicer_platform/pole_collision.obj" />
    <mesh
      name="solar_panels_collision"
      file="servicer_platform/solar_panels_collision.obj"
    />
  </asset>

  <worldbody>
    <light pos="1 1 1.5" dir="0 0 -1" directional="true" />
    <camera
      name="scene_camera"
      pos="-0.3 0.3 1.0"
      fovy="58"
      mode="fixed"
      resolution="1920 1080"
      euler="0 -1.0472 -1.5708"
    />
    <site
      name="scene_camera_optical_frame"
      pos="-0.3 0.3 1.0"
      euler="3.1416 1.0472 1.5708"
      size="0.03"
    />
    <body name="servicer_platform_with_arm">
      <camera
        name="servicer_camera"
        pos="0.6 1 0"
        fovy="58"
        mode="fixed"
        resolution="1920 1080"
        euler="1.5708 -2 0.0"
        user="1"
      />
      <site
        name="servicer_camera_optical_frame"
        pos="0.6 1 0"
        euler="-1.5708 2 0.0"
        size="0.03"
      />
      <inertial pos="0 0 0" mass="1000" diaginertia="100 100 100" />
      <joint name="servicer_platform_x" type="slide" axis="1 0 0" />
      <joint name="servicer_platform_y" type="slide" axis="0 1 0" />
      <joint name="servicer_platform_z" type="slide" axis="0 0 1" />
      <joint name="servicer_platform_roll" type="hinge" axis="1 0 0" />
      <joint name="servicer_platform_pitch" type="hinge" axis="0 1 0" />
      <joint name="servicer_platform_yaw" type="hinge" axis="0 0 1" />
      <body name="servicer_platform" pos="-0.2874 0.6350 -0.0508" euler="0 0 0">
        <geom
          class="visual"
          type="mesh"
          mesh="epastar"
          material="servicer_platform_silver"
          density="200"
        />
        <geom
          class="visual"
          type="mesh"
          mesh="interface"
          material="servicer_platform_gold"
          density="200"
        />
        <geom
          class="visual"
          type="mesh"
          mesh="rpo_suite"
          material="servicer_platform_silver"
          density="200"
        />
        <geom
          class="visual"
          type="mesh"
          mesh="pole"
          material="servicer_platform_silver"
          density="200"
        />
        <geom
          class="visual"
          type="mesh"
          mesh="solar_panels"
          material="servicer_platform_blue"
          density="200"
        />
        <geom
          class="collision"
          type="mesh"
          mesh="epastar_collision"
          density="1"
        />
        <geom
          class="collision"
          type="mesh"
          mesh="interface_collision"
          density="1"
        />
        <geom
          class="collision"
          type="mesh"
          mesh="rpo_suite_collision"
          density="1"
        />
        <geom class="collision" type="mesh" mesh="pole_collision" density="1" />
        <geom
          class="collision"
          type="mesh"
          mesh="solar_panels_collision"
          density="1"
        />
      </body>
      <body name="gen3_7dof" pos="0.5 0 0" quat="0.5 0.5 0.5 0.5">
        <include file="gen3_7dof_body.xml" />
      </body>
    </body>
  </worldbody>

  <actuator>
    <motor
      name="servicer_platform_x"
      joint="servicer_platform_x"
      ctrllimited="true"
      ctrlrange="-100 100"
    />
    <motor
      name="servicer_platform_y"
      joint="servicer_platform_y"
      ctrllimited="true"
      ctrlrange="-100 100"
    />
    <motor
      name="servicer_platform_z"
      joint="servicer_platform_z"
      ctrllimited="true"
      ctrlrange="-100 100"
    />
    <motor
      name="servicer_platform_roll"
      joint="servicer_platform_roll"
      ctrllimited="true"
      ctrlrange="-100 100"
    />
    <motor
      name="servicer_platform_pitch"
      joint="servicer_platform_pitch"
      ctrllimited="true"
      ctrlrange="-100 100"
    />
    <motor
      name="servicer_platform_yaw"
      joint="servicer_platform_yaw"
      ctrllimited="true"
      ctrlrange="-100 100"
    />
  </actuator>
</mujoco>
