<!-- UR5e inspired from https://github.com/google-deepmind/mujoco_menagerie/tree/main/universal_robots_ur5e -->
<mujoco model="fanuc scene">
  <compiler angle="radian" autolimits="true" />
  <option integrator="implicit" />
  <include file="lrmate200id/lrmate200id_globals.xml" />
  <include file="tool.xml" />
  <include file="box-welds.xml" />

  <asset>
    <!-- Define textures and materials -->
    <texture name="wood" type="cube" file="assets/wood.png" />
    <material name="wood" texture="wood" texrepeat="1 1" />

    <!-- Define AprilTag textures -->
    <texture name="apriltag1" type="2d" file="assets/tag36_11_00000.png" />
    <texture name="apriltag2" type="2d" file="assets/tag36_11_00001.png" />

    <!-- Define block materials with AprilTags -->
    <material
      name="apriltag_material1"
      texture="apriltag1"
      texuniform="false"
    />
    <material
      name="apriltag_material2"
      texture="apriltag2"
      texuniform="false"
    />
  </asset>

  <statistic center="0.3 0 0.4" extent="0.8" />

  <visual>
    <headlight diffuse="0.6 0.6 0.6" ambient="0.1 0.1 0.1" specular="0 0 0" />
    <rgba haze="0.15 0.25 0.35 1" />
    <global azimuth="120" elevation="-20" />
  </visual>

  <asset>
    <texture
      type="skybox"
      builtin="gradient"
      rgb1="0.3 0.5 0.7"
      rgb2="0 0 0"
      width="512"
      height="3072"
    />
    <texture
      type="2d"
      name="groundplane"
      builtin="checker"
      mark="edge"
      rgb1="0.2 0.3 0.4"
      rgb2="0.1 0.2 0.3"
      markrgb="0.8 0.8 0.8"
      width="300"
      height="300"
    />
    <material
      name="groundplane"
      texture="groundplane"
      texuniform="true"
      texrepeat="5 5"
      reflectance="0.2"
    />
  </asset>
  <asset>
    <mesh name="cube" file="assets/Cube.stl" />
    <mesh name="concave_hemisphere" file="assets/concave_hemisphere.stl" />
    <mesh name="convex_hemisphere" file="assets/convex_hemisphere.stl" />
  </asset>

  <worldbody>
    <light pos="0 0 1.5" dir="0 0 -1" directional="true" />
    <geom
      name="floor"
      pos="0 0 0"
      size="0 0 0.05"
      type="plane"
      material="groundplane"
    />
    <!-- Define the table -->
    <!-- <body name="table" pos="0 1 0.45">
      <geom type="box" size="0.5 0.5 0.025" material="wood" />
    </body> -->
    <!-- Define the block with AprilTags on each face -->
    <!-- <body name="block1" pos="0.2 0.75 0.575">
      <freejoint name="block1" />
      <site name="block1" pos="0 0 0" />
      <geom
        type="box"
        size="0.025 0.025 0.025"
        rgba="1 1 1 1"
        material="apriltag_material1"
      />
    </body>
    <body name="block2" pos="0.0 0.75 0.575">
      <freejoint name="block2" />
      <site name="block2" pos="0 0 0" />
      <geom class="visual" mesh="cube" pos="0 0 -0.03" />
      <geom class="collision" type="box" size="0.025 0.025 0.025" pos="0 0 0" />
    </body>
    <body name="block3" pos="-0.2 0.75 0.575">
      <freejoint name="block3" />
      <site name="block3" pos="0 0 0" />
      <geom
        type="box"
        size="0.025 0.025 0.025"
        rgba="1 1 1 1"
        material="apriltag_material2"
      />
    </body> -->
    <!-- Add a scene camera -->
    <!-- <site
      name="scene_camera_optical_frame"
      pos="1.1 1.1 1.5"
      euler="2.6 -0.8 -2.14"
    />
    <camera
      name="scene_camera"
      pos="1.1 1.1 1.5"
      fovy="58"
      mode="fixed"
      resolution="640 480"
      euler="-0.54 0.8 2.14"
    /> -->

    <!-- Add a scene camera -->
    <!-- <camera
      name="scene_camera"
      pos="0.0 1.5 2.6"
      fovy="58"
      mode="fixed"
      resolution="640 480"
      xyaxes="-1.000 0.000 -0.000 -0.000 -0.878 0.479"
    />
    <site
      name="scene_camera_optical_frame"
      pos="0.0 1.5 2.6"
      xyaxes="-1.000 0.000 -0.000 0.000 0.878 -0.479"
    /> -->


    <body name="arm_pedestal" pos="0.0 0.0 0.15">
      <geom type="box" size="0.2 0.2 0.15" />
      <geom type="box" size="0.06 0.01 0.01" pos="0.23 0.03 0.1" />
      <geom type="box" size="0.06 0.01 0.01" pos="0.23 -0.03 0.1" />
      <site name="tool_holder_site" pos="0.25 0 0.15" euler="3.1415 0 0" />
    </body>
    <!-- x 0.2+0.06/2 -->
    <!-- <body name="tool_mount" pos="0.23 0.0 0.3" euler="3.1415 0 0">
      <site name="tool_holder_site" />
      <include file="tool.xml" />
    </body> -->
    <!-- <body name="arm_pedestal" pos="0.0 0.0 0.15"> -->
      <!-- Pedestal -->
      <!-- <geom type="box" size="0.2 0.2 0.15" /> -->
      <!-- Tool holder -->
      <!-- x 0.2+0.03 -->
      <!-- <geom type="box" size="0.03 0.01 0.01" pos="0.23 0.03 0.1" /> -->
      <!-- <geom type="box" size="0.03 0.01 0.01" pos="0.23 -0.03 0.1" /> -->
      <!--<site name="tool_holder_site" pos="0.25 0 0.15" euler="3.1415 0 0" />-->
    <!-- </body> -->
    <body name="arm_mount" pos="0.0 0.0 0.3">
      <include file="lrmate200id/lrmate200id.xml" />
    </body>
    <!-- <body name="arm_mount" pos="0.0 0.0 0.3">
      <include file="lrmate200id/lrmate200id.xml" />
    </body> -->







    <!-- BIN PICKING SCENARIO -->
    <!-- Define the table for bin picking scenario -->
    <body name="bin_table" pos="0 0.6 0.2">
      <geom type="box" size="0.4 0.4 0.025" material="wood" />

      <!-- https://github.com/PickNikRobotics/moveit_studio_ur_ws/blob/pr-add-bin-picking-reference-app-2/src/picknik_ur_epick_config/description/environment.xacro -->
      <!-- <xacro:property name="bin_x" value="${24 * 0.0254}" />
      <xacro:property name="bin_y" value="${15 * 0.0254}" />
      <xacro:property name="bin_z" value="${7.5 * 0.0254}" />
      <xacro:property name="bin_wall" value="0.025" />
      <xacro:property name="bin_bottom" value="0.005" /> -->

      <body name="left_bin" pos="-0.25 0 0.025" quat="0.707 0 0 0.707">
        <!-- <geom type="box" size="1 1 .01" pos="0.5 0.5 0" rgba=".5 .5 .5 1"/>
        <geom type="box" size="1 1 .01" pos="0 0 0" rgba=".5 0 0 1"/> -->
        <!-- Bottom -->
        <!-- <box size="${x_length} ${y_length} ${bottom_thickness}"/> -->
        <!-- <origin xyz="${x_length/2} ${y_length/2} ${bottom_thickness/2}"/> -->
        <geom type="box" size="0.3048 0.1905 0.0025" pos="0 0 0.0025" rgba=".5 .5 .5 1"/>
        <!-- Back -->
        <!-- <box size="${side_wall_thickness} ${y_length} ${z_length}"/> -->
        <!-- <origin xyz="${side_wall_thickness/2} ${y_length/2} ${z_length/2}"/> -->
        <!-- <geom type="box" size="0.0125 0.190 0.09525" pos="0.3048-0.0125 0 0.0025+0.09525" rgba="1 .5 .5 1"/> -->
        <geom type="box" size="0.0125 0.190 0.09525" pos="0.2923 0 0.09775" rgba=".5 .5 .5 1"/>
        <!-- Front -->
        <!-- <box size="${side_wall_thickness} ${y_length} ${z_length}"/> -->
        <!-- <origin xyz="${x_length - side_wall_thickness/2} ${y_length/2} ${z_length/2}"/> -->
        <!-- <geom type="box" size="0.0125 0.190 0.09525" pos="-0.3048+0.0125 0 0.0025+0.09525" rgba="1 .5 .5 1"/> -->
        <geom type="box" size="0.0125 0.190 0.09525" pos="-0.2923 0 0.09775" rgba=".5 .5 .5 1"/>
        <!-- Right -->
        <!-- <box size="${x_length} ${side_wall_thickness} ${z_length}"/> -->
        <!-- <origin xyz="${x_length/2} ${side_wall_thickness/2} ${z_length/2}"/> -->
        <!-- <geom type="box" size="0.3048 0.0125 0.09525" pos="0 0.1905-0.0125 0.09775" rgba=".5 .5 .5 1"/> -->
        <geom type="box" size="0.3048 0.0125 0.09525" pos="0 0.178 0.09775" rgba=".5 .5 .5 1"/>
        <!-- Left -->
        <!-- <box size="${x_length} ${side_wall_thickness} ${z_length}"/> -->
        <!-- <origin xyz="${x_length/2} ${y_length - side_wall_thickness/2} ${z_length/2}"/> -->
        <geom type="box" size="0.3048 0.0125 0.09525" pos="0 -0.178 0.09775" rgba=".5 .5 .5 1"/>
      </body>

      <body name="right_bin" pos="0.25 0 0.025" quat="0.707 0 0 0.707">
        <geom type="box" size="0.3048 0.1905 0.0025" pos="0 0 0.0025" rgba=".5 .5 .5 1"/>
        <geom type="box" size="0.0125 0.190 0.09525" pos="0.2923 0 0.09775" rgba=".5 .5 .5 1"/>
        <geom type="box" size="0.0125 0.190 0.09525" pos="-0.2923 0 0.09775" rgba=".5 .5 .5 1"/>
        <geom type="box" size="0.3048 0.0125 0.09525" pos="0 0.178 0.09775" rgba=".5 .5 .5 1"/>
        <geom type="box" size="0.3048 0.0125 0.09525" pos="0 -0.178 0.09775" rgba=".5 .5 .5 1"/>
      </body>
    </body>

    
    <!-- 4 7 2 -->
    <!-- 3 6 2 -->
    <replicate count="3" sep="-" offset=".07 0 0">
      <replicate count="6" sep="-" offset="0 .07 0">
        <replicate count="2" sep="-" offset="0 0 0.5">
          <body name="sphere-0" pos="-0.35 0.4 0.5">
            <joint type="slide" axis="1 0 0" group="3"/>
            <joint type="slide" axis="0 1 0" group="3"/>
            <joint type="slide" axis="0 0 1" group="3"/>
            <geom type="box" size="0.025 0.025 0.025" condim="1" priority="1" rgba="0.8 0.2 0.1 1"/>
          </body>
        </replicate>
      </replicate>
    </replicate>

    <!-- 3 6 2 -->
    <replicate count="3" sep="-" offset=".07 0 0">
      <replicate count="6" sep="-" offset="0 .07 0">
        <replicate count="2" sep="-" offset="0 0 0.5">
          <body name="sphere-1" pos="-0.3 0.45 0.75">
            <joint type="slide" axis="1 0 0" group="3"/>
            <joint type="slide" axis="0 1 0" group="3"/>
            <joint type="slide" axis="0 0 1" group="3"/>
            <geom type="box" size="0.025 0.025 0.025" condim="1" priority="1" rgba="0.8 0.2 0.1 1"/>
          </body>
        </replicate>
      </replicate>
    </replicate>

    <!-- <replicate count="1" sep="-" offset=".07 0 0">
      <replicate count="1" sep="-" offset="0 .07 0">
        <replicate count="2" sep="-" offset="0 0 .1">
          <body name="box-2" pos="-0.3 1.0 1.0">
            <joint type="slide" axis="1 0 0" group="3"/>
            <joint type="slide" axis="0 1 0" group="3"/>
            <joint type="slide" axis="0 0 1" group="3"/>
            <geom size="0.1" condim="1" priority="1" rgba="0.8 0.2 0.1 1"/>
          </body>
        </replicate>
      </replicate>
    </replicate> -->



    <!-- ASSEMBLY SCENARIO -->

    <!-- Define the table for assembly scenario -->
    <!-- y -0.2-0.2 -->
    <body name="assembly_table" pos="0 -0.4 0.2">
      <geom type="box" size="0.6 0.2 0.025" rgba="0.1 0.1 0.1 1" />
    </body>
    <!-- z 0.225+.005+.0001 -->
    <body name="shelf" pos="0.25 -0.4 0.2301">
      <geom type="box" size="0.2 0.1 0.005" material="wood" />
      <freejoint/>
    </body>
    <!-- x -0.05-0.025 -->
    <!-- z 0.225+.05+.0001 -->
    <body name="stud1" pos="-0.075 -0.4 0.2751">
      <geom type="box" size="0.025 0.1 0.05" material="wood" />
      <freejoint/>
    </body>
    <!-- x -0.45+0.025 -->
    <!-- z 0.225+.05+.0001 -->
    <body name="stud2" pos="-0.425 -0.4 0.2751">
      <geom type="box" size="0.025 0.1 0.05" material="wood" />
      <freejoint/>
    </body>

    <!-- Left stud jig -->
    <!-- x -0.45-0.01-0.0001 -->
    <!-- z 0.225+.025 -->
    <body name="jig1_1" pos="-0.4601 -0.4 0.25">
      <geom type="cylinder" size="0.01 0.025" rgba="0.1 0.1 0.1 1" />
    </body>
    <!-- x -0.4+0.01+0.0001 -->
    <body name="jig1_2" pos="-0.3899 -0.4 0.25">
      <geom type="cylinder" size="0.01 0.025" rgba="0.1 0.1 0.1 1" />
    </body>
    <!-- y -0.5-0.01-0.0001 -->
    <body name="jig1_3" pos="-0.425 -0.5101 0.25">
      <geom type="cylinder" size="0.01 0.025" rgba="0.1 0.1 0.1 1" />
    </body>
    <!-- y -0.3+0.01+0.0001 -->
    <body name="jig1_4" pos="-0.425 -0.2899 0.25">
      <geom type="cylinder" size="0.01 0.025" rgba="0.1 0.1 0.1 1" />
    </body>

    <!-- Right stud jig -->


    <!-- z 0.225+.005+.0001 -->
    <!-- <body name="shelf2" pos="-0.25 -0.75 0.4">
      <geom type="box" size="0.2 0.1 0.005" material="wood" />
      <freejoint/>
    </body> -->

<!--
1m wide
.4m wide sheet
stud      <geom type="box" size="0.05 0.4 0.1" material="wood" />
-->

    <!-- REGISTER AND RASTERIZE SCENARIO -->
    
    <geom type="mesh" mesh="convex_hemisphere" pos="0.75 0 .6" euler="0 0 1.5708"/>
    <site name="convex_hemisphere" pos="0.75 0 .6" euler="0 0 1.5708"/>
    <geom type="mesh" mesh="concave_hemisphere" pos="0.65 0 1" euler="0 0 -1.5708"/>
    <site name="concave_hemisphere" pos="0.65 0 1" euler="0 0 -1.5708"/>
    <geom type="box" pos="0.8 0 .8" size=".05 .4 0.8" />

 









  </worldbody>

  <!-- Define weld constraints between the robot flange (tool0) and the gripper, and between the suction cup (tool_tip)
       and the blocks in the scene -->
  <equality>
    <weld
      name="tool_attachment"
      body1="tool0"
      body2="gripper_base"
      active="false"
      torquescale="1"
    />
    <!-- <weld
      name="suction_cup_block1"
      body1="tool_tip"
      body2="block1"
      active="false"
      torquescale="1"
    />
    <weld
      name="suction_cup_block2"
      body1="tool_tip"
      body2="block2"
      active="false"
      torquescale="1"
    />
    <weld
      name="suction_cup_block3"
      body1="tool_tip"
      body2="block3"
      active="false"
      torquescale="1"
    /> -->
  </equality>
</mujoco>
