<?xml version="1.0" ?>
<!-- =================================================================================== -->
<!-- |    This document was autogenerated by xacro from moveit_pro_kuka_configs/kr-16/description/kr16.xacro | -->
<!-- |    EDITING THIS FILE BY HAND IS NOT RECOMMENDED                                 | -->
<!-- =================================================================================== -->
<robot name="kr16">
  <ros2_control name="kr16_r2010_2" type="system">
    <hardware>
      <plugin>kuka_mock_hardware_interface::KukaMockHardwareInterface</plugin>
      <param name="cycle_time_ms">4</param>
      <param name="roundtrip_time_micro">0</param>
      <param name="mock_sensor_commands">false</param>
      <param name="state_following_offset">0.0</param>
    </hardware>
    <joint name="joint_1">
      <command_interface name="position"/>
      <state_interface name="position">
        <param name="initial_value">0.0</param>
      </state_interface>
    </joint>
    <joint name="joint_2">
      <command_interface name="position"/>
      <state_interface name="position">
        <param name="initial_value">-1.5708</param>
      </state_interface>
    </joint>
    <joint name="joint_3">
      <command_interface name="position"/>
      <state_interface name="position">
        <param name="initial_value">1.5708</param>
      </state_interface>
    </joint>
    <joint name="joint_4">
      <command_interface name="position"/>
      <state_interface name="position">
        <param name="initial_value">0.0</param>
      </state_interface>
    </joint>
    <joint name="joint_5">
      <command_interface name="position"/>
      <state_interface name="position">
        <param name="initial_value">0.0</param>
      </state_interface>
    </joint>
    <joint name="joint_6">
      <command_interface name="position"/>
      <state_interface name="position">
        <param name="initial_value">0.0</param>
      </state_interface>
    </joint>
  </ros2_control>
  <link name="world"/>
  <link name="base_link">
    <collision>
      <geometry>
        <mesh filename="package://kuka_cybertech_support/meshes/kr16_r2010_2/collision/base_link.stl"/>
      </geometry>
      <origin rpy="-0.0 0.0 -0.0" xyz="0.0 0.0 0.0"/>
    </collision>
    <visual>
      <geometry>
        <mesh filename="package://kuka_cybertech_support/meshes/kr16_r2010_2/visual/base_link.stl"/>
      </geometry>
      <origin rpy="-0.0 0.0 -0.0" xyz="0.0 0.0 0.0"/>
    </visual>
  </link>
  <link name="link_1">
    <collision>
      <geometry>
        <mesh filename="package://kuka_cybertech_support/meshes/kr16_r2010_2/collision/link_1.stl"/>
      </geometry>
      <origin rpy="-0.0 0.0 -0.0" xyz="0.0 0.0 0.0"/>
    </collision>
    <visual>
      <geometry>
        <mesh filename="package://kuka_cybertech_support/meshes/kr16_r2010_2/visual/link_1.stl"/>
      </geometry>
      <origin rpy="-0.0 0.0 -0.0" xyz="0.0 0.0 0.0"/>
    </visual>
  </link>
  <link name="link_2">
    <collision>
      <geometry>
        <mesh filename="package://kuka_cybertech_support/meshes/kr16_r2010_2/collision/link_2.stl"/>
      </geometry>
      <origin rpy="-0.0 0.0 -0.0" xyz="0.0 0.0 0.0"/>
    </collision>
    <visual>
      <geometry>
        <mesh filename="package://kuka_cybertech_support/meshes/kr16_r2010_2/visual/link_2.stl"/>
      </geometry>
      <origin rpy="-0.0 0.0 -0.0" xyz="0.0 0.0 0.0"/>
    </visual>
  </link>
  <link name="link_3">
    <collision>
      <geometry>
        <mesh filename="package://kuka_cybertech_support/meshes/kr16_r2010_2/collision/link_3.stl"/>
      </geometry>
      <origin rpy="-0.0 0.0 -0.0" xyz="0.0 0.0 0.0"/>
    </collision>
    <visual>
      <geometry>
        <mesh filename="package://kuka_cybertech_support/meshes/kr16_r2010_2/visual/link_3.stl"/>
      </geometry>
      <origin rpy="-0.0 0.0 -0.0" xyz="0.0 0.0 0.0"/>
    </visual>
  </link>
  <link name="link_4">
    <collision>
      <geometry>
        <mesh filename="package://kuka_cybertech_support/meshes/kr16_r2010_2/collision/link_4.stl"/>
      </geometry>
      <origin rpy="-0.0 0.0 -0.0" xyz="0.0 0.0 0.0"/>
    </collision>
    <visual>
      <geometry>
        <mesh filename="package://kuka_cybertech_support/meshes/kr16_r2010_2/visual/link_4.stl"/>
      </geometry>
      <origin rpy="-0.0 0.0 -0.0" xyz="0.0 0.0 0.0"/>
    </visual>
  </link>
  <link name="link_5">
    <collision>
      <geometry>
        <mesh filename="package://kuka_cybertech_support/meshes/kr16_r2010_2/collision/link_5.stl"/>
      </geometry>
      <origin rpy="-0.0 0.0 -0.0" xyz="0.0 0.0 0.0"/>
    </collision>
    <visual>
      <geometry>
        <mesh filename="package://kuka_cybertech_support/meshes/kr16_r2010_2/visual/link_5.stl"/>
      </geometry>
      <origin rpy="-0.0 0.0 -0.0" xyz="0.0 0.0 0.0"/>
    </visual>
  </link>
  <link name="link_6">
    <collision>
      <geometry>
        <mesh filename="package://kuka_cybertech_support/meshes/kr16_r2010_2/collision/link_6.stl"/>
      </geometry>
      <origin rpy="-0.0 0.0 -0.0" xyz="0.0 0.0 0.0"/>
    </collision>
    <visual>
      <geometry>
        <mesh filename="package://kuka_cybertech_support/meshes/kr16_r2010_2/visual/link_6.stl"/>
      </geometry>
      <origin rpy="-0.0 0.0 -0.0" xyz="0.0 0.0 0.0"/>
    </visual>
  </link>
  <joint name="world-base_link" type="fixed">
    <parent link="world"/>
    <child link="base_link"/>
    <origin rpy="0 0 0" xyz="0 0 0"/>
  </joint>
  <joint name="joint_1" type="revolute">
    <axis xyz="0.0 0.0 1.0"/>
    <child link="link_1"/>
    <limit effort="1905.3" lower="-3.2288591162E0" upper="3.2288591161895095E0" velocity="3.490658503988659"/>
    <origin rpy="-3.141592653589793 0.0 -0.0" xyz="0.0 0.0 0.0"/>
    <parent link="base_link"/>
  </joint>
  <joint name="joint_2" type="revolute">
    <axis xyz="0.0 0.0 1.0"/>
    <child link="link_2"/>
    <limit effort="1633.6259859" lower="-3.2288591161895095E0" upper="1.1344640137963142E0" velocity="3.0543261909900767"/>
    <origin rpy="1.5707963267948966 0.0 -0.0" xyz="0.16 0.0 -0.52"/>
    <parent link="link_1"/>
  </joint>
  <joint name="joint_3" type="revolute">
    <axis xyz="0.0 0.0 1.0"/>
    <child link="link_3"/>
    <limit effort="850.58019869" lower="-2.4085543677521746E0" upper="3.0543261909900767E0" velocity="3.3161255787892263"/>
    <origin rpy="0.0 0.0 -1.5707963267948966" xyz="0.98 0.0 0.0"/>
    <parent link="link_2"/>
  </joint>
  <joint name="joint_4" type="revolute">
    <axis xyz="0.0 0.0 1.0"/>
    <child link="link_4"/>
    <limit effort="266.21043332" lower="-6.1086523819801535E0" upper="6.1086523819801535E0" velocity="7.504915783575617"/>
    <origin rpy="1.5707963267948966 0.0 -0.0" xyz="0.15 0.0 0.0"/>
    <parent link="link_3"/>
  </joint>
  <joint name="joint_5" type="revolute">
    <axis xyz="0.0 0.0 1.0"/>
    <child link="link_5"/>
    <limit effort="255.43776663" lower="-2.268928027593E0" upper="2.2689280275926285E0" velocity="7.504915783575617"/>
    <origin rpy="-1.5707963267948966 0.0 -0.0" xyz="0.0 0.0 -0.86"/>
    <parent link="link_4"/>
  </joint>
  <joint name="joint_6" type="revolute">
    <axis xyz="0.0 0.0 1.0"/>
    <child link="link_6"/>
    <limit effort="111.65796" lower="-6.1086523819801535E0" upper="6.1086523819801535E0" velocity="10.995574287564276"/>
    <origin rpy="1.5707963267948966 0.0 -0.0" xyz="0.0 0.0 0.0"/>
    <parent link="link_5"/>
  </joint>
  <!-- ROS-Industrial 'base' frame - equivalent of 'KUKA ROBROOT'-->
  <link name="base"/>
  <joint name="base_link-base" type="fixed">
    <origin rpy="0 0 0" xyz="0 0 0"/>
    <parent link="base_link"/>
    <child link="base"/>
  </joint>
  <!-- ROS-Industrial 'flange' frame - attachment point for EEF models -->
  <link name="flange"/>
  <joint name="link6-flange" type="fixed">
    <child link="flange"/>
    <origin rpy="0 1.5707963267948966 -0.0" xyz="0.0 0.0 -0.153"/>
    <parent link="link_6"/>
  </joint>
  <!-- ROS-Industrial 'tool0' frame - all-zeros tool frame -->
  <link name="tool0"/>
  <joint name="link6-tool0" type="fixed">
    <child link="tool0"/>
    <origin rpy="0 3.141592653589793 -0.0" xyz="0.0 0.0 -0.153"/>
    <parent link="link_6"/>
  </joint>
  <ros2_control name="mujoco_control" type="system">
    <hardware>
      <plugin>picknik_mujoco_ros/MujocoSystem</plugin>
      <param name="mujoco_model">description/scene.xml</param>
      <param name="mujoco_model_package">kr-16</param>
      <!-- The rate <camera> data is published at -->
      <param name="render_publish_rate">10</param>
      <!-- The rate transforms to <site> poses are published at -->
      <param name="tf_publish_rate">60</param>
      <!-- The rate <rangefinder> data is published at -->
      <param name="lidar_publish_rate">10</param>
      <!-- Whether to launch the MuJoCo interactive viewer -->
      <param name="mujoco_viewer">false</param>
    </hardware>
  </ros2_control>
</robot>
