<?xml version='1.0' encoding='utf-8'?>
<mujoco model="tool0">
  <compiler angle="radian" autolimits="true" meshdir="assets"/>

  <default>
    <!-- Geom defaults -->
    <default class="visual">
      <geom group="2" type="mesh" contype="0" conaffinity="0"/>
    </default>
    <default class="collision">
      <geom group="3" type="mesh"/>
    </default>
  </default>

  <asset>
    <texture type="2d" name="groundplane" builtin="checker" mark="edge" rgb1="0.2 0.3 0.4" rgb2="0.1 0.2 0.3" markrgb="0.8 0.8 0.8" width="300" height="300"/>
    <material name="groundplane" texture="groundplane" texuniform="true" texrepeat="5 5" reflectance="0.2"/>
    <!-- Tool-Base geometries -->
    <mesh file="tool_base/tool_base.obj"/>
    <mesh name="base_geometry_0" file="tool_base/geometry_0.stl"/>
    <mesh name="base_geometry_1" file="tool_base/geometry_1.stl"/>
    <mesh name="base_geometry_2" file="tool_base/geometry_2.stl"/>
    <mesh name="base_geometry_3" file="tool_base/geometry_3.stl"/>
    <mesh name="base_geometry_4" file="tool_base/geometry_4.stl"/>
    <mesh name="base_geometry_5" file="tool_base/geometry_5.stl"/>
    <mesh name="base_geometry_6" file="tool_base/geometry_6.stl"/>
    <mesh name="base_geometry_7" file="tool_base/geometry_7.stl"/>

    <!-- Tool-Tool geometries -->
    <mesh file="tool0_tool/tool0_tool.obj"/>
    <mesh name="tool_geometry_0" file="tool0_tool/geometry_0.stl"/>
    <mesh name="tool_geometry_1" file="tool0_tool/geometry_1.stl"/>
    <mesh name="tool_geometry_2" file="tool0_tool/geometry_2.stl"/>
    <mesh name="tool_geometry_3" file="tool0_tool/geometry_3.stl"/>
    <mesh name="tool_geometry_4" file="tool0_tool/geometry_4.stl"/>
    <mesh name="tool_geometry_5" file="tool0_tool/geometry_5.stl"/>
    <mesh name="tool_geometry_6" file="tool0_tool/geometry_6.stl"/>
  </asset>

  <worldbody>
    <light pos="0 0 1.5" dir="0 0 -1" directional="true"/>
    <geom name="floor" pos="0 0 0" size="0 0 0.05" type="plane" material="groundplane"/>

    <!-- Tool -->
    <body name="tool_base" pos="0 0 0.1" quat="1 0 0 0">
      <geom quat="1 0 0 0" mesh="tool_base" class="visual"/>
      <geom quat="1 0 0 0" mesh="base_geometry_0" class="collision"/>
      <geom quat="1 0 0 0" mesh="base_geometry_1" class="collision"/>
      <geom quat="1 0 0 0" mesh="base_geometry_2" class="collision"/>
      <geom quat="1 0 0 0" mesh="base_geometry_3" class="collision"/>
      <geom quat="1 0 0 0" mesh="base_geometry_4" class="collision"/>
      <geom quat="1 0 0 0" mesh="base_geometry_5" class="collision"/>
      <geom quat="1 0 0 0" mesh="base_geometry_6" class="collision"/>
      <geom quat="1 0 0 0" mesh="base_geometry_7" class="collision"/>
      <body name="tool_tool" pos="0 0 0" quat="-1 0 0 0">
        <joint name="tool_slide_joint" type="slide" axis="0 1 0" pos="0 0 0.1" range="-0.015 0.015"/>
        <geom quat="1 0 0 0" mesh="tool0_tool" class="visual"/>
        <geom quat="1 0 0 0" mesh="tool_geometry_0" class="collision"/>
        <geom quat="1 0 0 0" mesh="tool_geometry_1" class="collision"/>
        <geom quat="1 0 0 0" mesh="tool_geometry_2" class="collision"/>
        <geom quat="1 0 0 0" mesh="tool_geometry_3" class="collision"/>
        <geom quat="1 0 0 0" mesh="tool_geometry_4" class="collision"/>
        <geom quat="1 0 0 0" mesh="tool_geometry_5" class="collision"/>
        <geom quat="1 0 0 0" mesh="tool_geometry_6" class="collision"/>
      </body>
    </body>
  </worldbody>

  <actuator>
    <!-- gearing puts this force actuator in units of lbf -->
    <general name="tool_slide_joint" joint="tool_slide_joint" gear="4.44822" ctrlrange="-150 150" user="115"/>
  </actuator>

  <contact>
    <exclude name="tool_contact_exclude" body1="tool_base" body2="tool_tool"/>
  </contact>

  <keyframe>
    <key name="default" qpos="0" ctrl="115"/>
  </keyframe>
</mujoco>
