<mujoco model="fanuc scene">
  <compiler angle="radian" autolimits="true" />
  <option integrator="implicit" />

  <asset>
    <!-- Define textures and materials -->
    <texture name="wood" type="cube" file="assets/wood.png" />
    <material name="wood" texture="wood" texrepeat="1 1" />
    <mesh name="bowl" file="assets/bowl.stl" />

    <texture
      type="skybox"
      builtin="gradient"
      rgb1="0.3 0.5 0.7"
      rgb2="0 0 0"
      width="512"
      height="3072"
    />
    <texture
      type="2d"
      name="groundplane"
      builtin="checker"
      mark="edge"
      rgb1="0.2 0.3 0.4"
      rgb2="0.1 0.2 0.3"
      markrgb="0.8 0.8 0.8"
      width="300"
      height="300"
    />
    <material
      name="groundplane"
      texture="groundplane"
      texuniform="true"
      texrepeat="5 5"
      reflectance="0.2"
    />
  </asset>

  <statistic center="0.3 0 0.4" extent="0.8" />

  <visual>
    <headlight diffuse="0.6 0.6 0.6" ambient="0.1 0.1 0.1" specular="0 0 0" />
    <rgba haze="0.15 0.25 0.35 1" />
    <global azimuth="120" elevation="-20" />
  </visual>

  <!-- Add Fanuc support files -->
  <include file="lrmate200id/lrmate200id_globals.xml" />

  <worldbody>
    <light pos="0 0 1.5" dir="0 0 -1" directional="true" />
    <geom
      name="floor"
      pos="0 0 0"
      size="0 0 0.05"
      type="plane"
      material="groundplane"
    />
    <!-- Add a scene camera -->
    <camera
      name="scene_camera"
      pos="-1.15 0.000 1.900"
      fovy="58"
      mode="fixed"
      resolution="640 480"
      xyaxes="0.000 -1.000 0.000 0.713 0.000 0.701"
    />
    <site
      name="scene_camera_optical_frame"
      pos="-1.15 0.000 1.900"
      xyaxes="0.000 -1.000 0.000 -0.713 -0.000 -0.701"
    />

    <body name="arm_pedestal" pos="0.0 0.0 0.15">
      <geom type="box" size="0.2 0.2 0.15" />
      <geom type="box" size="0.06 0.01 0.01" pos="0.23 0.03 0.1" />
      <geom type="box" size="0.06 0.01 0.01" pos="0.23 -0.03 0.1" />
      <site name="tool_holder_site" pos="0.25 0 0.15" euler="3.1415 0 0" />
    </body>

    <body name="arm_mount" pos="0.0 0.0 0.3">
      <include file="lrmate200id/lrmate200id.xml" />
    </body>

    <!--  -->
    <!-- BIN PICKING SCENARIO -->
    <!--  -->
    <!-- Define the table for bin picking scenario -->
    <body name="bin_table" pos="0 0.6 0.2">
      <geom type="box" size="0.6 0.4 0.025" rgba="0.1 0.1 0.1 1" />

      <body name="left_bin" pos="-0.25 0 0.025" quat="0.707 0 0 0.707">
        <!-- <geom type="box" size="1 1 .01" pos="0.5 0.5 0" rgba=".5 .5 .5 1"/>
        <geom type="box" size="1 1 .01" pos="0 0 0" rgba=".5 0 0 1"/> -->
        <!-- Bottom -->
        <!-- <box size="${x_length} ${y_length} ${bottom_thickness}"/> -->
        <!-- <origin xyz="${x_length/2} ${y_length/2} ${bottom_thickness/2}"/> -->
        <!-- <geom type="box" size="0.3048 0.1905 0.0025" pos="0 0 0.0025" rgba=".11 .51 .86 1"/> -->
        <geom
          type="box"
          size="0.3048 0.1905 0.0025"
          pos="0 0 0.0025"
          rgba=".11 .51 .86 1"
        />
        <!-- Back -->
        <!-- <box size="${side_wall_thickness} ${y_length-side_wall_thickness} ${z_length}"/> -->
        <!-- <origin xyz="${side_wall_thickness/2} ${(y_length-side_wall_thickness)/2} ${z_length/2}"/> -->
        <!-- <geom type="box" size="0.0125 0.190 0.09525" pos="0.3048-0.0125 0 0.0025+0.09525" rgba="1 .5 .5 1"/> -->
        <geom
          type="box"
          size="0.0125 0.1655 0.09525"
          pos="0.2923 0 0.09775"
          rgba=".11 .51 .86 1"
        />
        <!-- Front -->
        <!-- <box size="${side_wall_thickness} ${y_length} ${z_length}"/> -->
        <!-- <origin xyz="${x_length - side_wall_thickness/2} ${y_length/2} ${z_length/2}"/> -->
        <!-- <geom type="box" size="0.0125 0.190 0.09525" pos="-0.3048+0.0125 0 0.0025+0.09525" rgba="1 .5 .5 1"/> -->
        <geom
          type="box"
          size="0.0125 0.1655 0.09525"
          pos="-0.2923 0 0.09775"
          rgba=".11 .51 .86 1"
        />
        <!-- Right -->
        <!-- <box size="${x_length} ${side_wall_thickness} ${z_length}"/> -->
        <!-- <origin xyz="${x_length/2} ${side_wall_thickness/2} ${z_length/2}"/> -->
        <!-- <geom type="box" size="0.3048 0.0125 0.09525" pos="0 0.1905-0.0125 0.09775" rgba=".5 .5 .5 1"/> -->
        <geom
          type="box"
          size="0.3048 0.0125 0.09525"
          pos="0 0.178 0.09775"
          rgba=".11 .51 .86 1"
        />
        <!-- Left -->
        <!-- <box size="${x_length} ${side_wall_thickness} ${z_length}"/> -->
        <!-- <origin xyz="${x_length/2} ${y_length - side_wall_thickness/2} ${z_length/2}"/> -->
        <geom
          type="box"
          size="0.3048 0.0125 0.09525"
          pos="0 -0.178 0.09775"
          rgba=".11 .51 .86 1"
        />
      </body>

      <body name="right_bin" pos="0.25 0 0.025" quat="0.707 0 0 0.707">
        <geom
          type="box"
          size="0.3048 0.1905 0.0025"
          pos="0 0 0.0025"
          rgba=".11 .51 .86 1"
        />
        <geom
          type="box"
          size="0.0125 0.1655 0.09525"
          pos="0.2923 0 0.09775"
          rgba=".11 .51 .86 1"
        />
        <geom
          type="box"
          size="0.0125 0.1655 0.09525"
          pos="-0.2923 0 0.09775"
          rgba=".11 .51 .86 1"
        />
        <geom
          type="box"
          size="0.3048 0.0125 0.09525"
          pos="0 0.178 0.09775"
          rgba=".11 .51 .86 1"
        />
        <geom
          type="box"
          size="0.3048 0.0125 0.09525"
          pos="0 -0.178 0.09775"
          rgba=".11 .51 .86 1"
        />
      </body>
    </body>

    <!-- First layer of cubes -->
    <!-- 3 6 2 -->
    <replicate count="3" sep="-" offset=".07 0 0">
      <replicate count="6" sep="-" offset="0 .07 0">
        <replicate count="2" sep="-" offset="0 0 0.5">
          <body name="sphere-0" pos="-0.35 0.4 0.5">
            <joint type="slide" axis="1 0 0" group="3" />
            <joint type="slide" axis="0 1 0" group="3" />
            <joint type="slide" axis="0 0 1" group="3" />
            <geom
              type="box"
              size="0.025 0.025 0.025"
              condim="1"
              priority="1"
              material="wood"
            />
          </body>
        </replicate>
      </replicate>
    </replicate>

    <!-- Second layer of cubes -->
    <!-- 3 6 2 -->
    <replicate count="3" sep="-" offset=".07 0 0">
      <replicate count="6" sep="-" offset="0 .07 0">
        <replicate count="2" sep="-" offset="0 0 0.5">
          <body name="sphere-1" pos="-0.3 0.45 0.75">
            <joint type="slide" axis="1 0 0" group="3" />
            <joint type="slide" axis="0 1 0" group="3" />
            <joint type="slide" axis="0 0 1" group="3" />
            <geom
              type="box"
              size="0.025 0.025 0.025"
              condim="1"
              priority="1"
              material="wood"
            />
          </body>
        </replicate>
      </replicate>
    </replicate>

    <!--  -->
    <!-- ASSEMBLY SCENARIO -->
    <!--  -->
    <!-- Define the table for assembly scenario -->
    <!-- y -0.2-0.2 -->
    <body name="assembly_table" pos="0 -0.4 0.2">
      <geom type="box" size="0.6 0.2 0.025" rgba="0.1 0.1 0.1 1" />
    </body>
    <!-- z 0.225+.005+.0001 -->
    <body name="shelf" pos="0.25 -0.4 0.2301">
      <geom type="box" size="0.2 0.1 0.005" material="wood" />
      <freejoint />
    </body>
    <!-- x -0.05-0.025 -->
    <!-- z 0.225+.05+.0001 -->
    <body name="stud1" pos="-0.075 -0.4 0.2751">
      <geom type="box" size="0.025 0.1 0.05" material="wood" />
      <freejoint />
    </body>
    <!-- x -0.45+0.025 -->
    <!-- z 0.225+.05+.0001 -->
    <body name="stud2" pos="-0.425 -0.4 0.2751">
      <geom type="box" size="0.025 0.1 0.05" material="wood" />
      <freejoint />
    </body>

    <!-- Left stud jig -->
    <!-- x -0.45-0.01-0.0001 -->
    <!-- z 0.225+.025 -->
    <body name="jig1_1" pos="-0.4601 -0.4 0.25">
      <geom type="cylinder" size="0.01 0.025" rgba="0.1 0.1 0.1 1" />
    </body>
    <!-- x -0.4+0.01+0.0001 -->
    <body name="jig1_2" pos="-0.3899 -0.4 0.25">
      <geom type="cylinder" size="0.01 0.025" rgba="0.1 0.1 0.1 1" />
    </body>
    <!-- y -0.5-0.01-0.0001 -->
    <body name="jig1_3" pos="-0.425 -0.5101 0.25">
      <geom type="cylinder" size="0.01 0.025" rgba="0.1 0.1 0.1 1" />
    </body>
    <!-- y -0.3+0.01+0.0001 -->
    <body name="jig1_4" pos="-0.425 -0.2899 0.25">
      <geom type="cylinder" size="0.01 0.025" rgba="0.1 0.1 0.1 1" />
    </body>

    <!-- Right stud jig -->
    <!-- TODO Decide if this would be useful -->

    <!--  -->
    <!-- REGISTER AND RASTERIZE SCENARIO -->
    <!--  -->
    <body name="stationary_rail" pos="1.1 0 0">
      <geom
        type="box"
        size="0.04 0.04 0.7"
        pos="0 0.8 0.7"
        rgba="0.21 0.88 0.55 1"
      />
      <geom
        type="box"
        size="0.24 0.04 0.04"
        pos="-0.2 0.8 1.44"
        rgba="0.21 0.88 0.55 1"
      />

      <geom
        type="box"
        size="0.04 0.04 0.7"
        pos="0 -0.8 0.7"
        rgba="0.21 0.88 0.55 1"
      />
      <geom
        type="box"
        size="0.24 0.04 0.04"
        pos="-0.2 -0.8 1.44"
        rgba="0.21 0.88 0.55 1"
      />

      <geom
        type="box"
        size="0.04 1.0 0.04"
        pos="-0.4 0.0 1.36"
        rgba="0.8 0.8 0.8 1"
      />

      <geom
        type="mesh"
        mesh="bowl"
        pos="-0.45 0.6 0.9"
        euler="0 1.5708 0"
        material="wood"
      />
      <site name="convex_bowl_1" pos="-0.45 0.6 0.9" euler="0 0 1.5708" />
      <geom
        type="box"
        size="0.01 0.02 0.16"
        pos="-0.4 0.6 1.22"
        rgba="0.1 0.1 0.1 1"
      />

      <geom
        type="mesh"
        mesh="bowl"
        pos="-0.45 0.2 0.9"
        euler="0 1.5708 0"
        material="wood"
      />
      <site name="convex_bowl_2" pos="-0.45 0.2 0.9" euler="0 0 1.5708" />
      <geom
        type="box"
        size="0.01 0.02 0.16"
        pos="-0.4 0.2 1.22"
        rgba="0.1 0.1 0.1 1"
      />

      <geom
        type="mesh"
        mesh="bowl"
        pos="-0.35 -0.2 0.9"
        euler="0 -1.5708 0"
        material="wood"
      />
      <site name="concave_bowl_1" pos="-0.456 -0.2 0.9" euler="0 0 -1.5708" />
      <geom
        type="box"
        size="0.01 0.02 0.16"
        pos="-0.4 -0.2 1.22"
        rgba="0.1 0.1 0.1 1"
      />

      <geom
        type="mesh"
        mesh="bowl"
        pos="-0.35 -0.6 0.9"
        euler="0 -1.5708 0"
        material="wood"
      />
      <site name="concave_bowl_2" pos="-0.456 -0.6 0.9" euler="0 0 -1.5708" />
      <geom
        type="box"
        size="0.01 0.02 0.16"
        pos="-0.4 -0.6 1.22"
        rgba="0.1 0.1 0.1 1"
      />
    </body>
  </worldbody>

  <!-- Add tool -->
  <include file="tool.xml" />

  <!-- Define weld constraints between the robot flange (tool0) and the gripper -->
  <equality>
    <weld
      name="tool_attachment"
      body1="tool0"
      body2="gripper_base"
      active="false"
      torquescale="1"
    />
  </equality>

  <!-- Add welds for suction gripping of cubes -->
  <include file="box-welds.xml" />

  <!-- TODO Add welds for suction gripping of assembly parts -->
</mujoco>
