<mujocoinclude>
  <body name="slide" childclass="slidecabinet">
    <geom pos="-0.135 0 -0.108" size="0.1338 0.18 0.012" type="box" />
    <geom pos="0.1344 0 0" size="0.1356 0.18 0.12" type="box" />
    <geom pos="-0.135 0 0.108" size="0.1338 0.18 0.012" type="box" />
    <geom pos="-0.2556 0 0" size="0.0132 0.18 0.096" type="box" />
    <geom pos="-0.12 0.1656 0" size="0.126 0.0144 0.096" type="box" />

    <geom
      class="slide_collision"
      pos="-0.135 0 -0.108"
      size="0.1338 0.18 0.012"
      type="box"
      mass=".2"
    />
    <geom
      class="slide_collision"
      pos="0.1344 0 0"
      size="0.1356 0.18 0.12"
      type="box"
      mass="1"
    />
    <geom
      class="slide_collision"
      pos="-0.135 0 0.108"
      size="0.1338 0.18 0.012"
      type="box"
      mass=".2"
    />
    <geom
      class="slide_collision"
      pos="-0.2556 0 0"
      size="0.0132 0.18 0.096"
      type="box"
      mass=".2"
    />
    <geom
      class="slide_collision"
      pos="-0.12 0.1656 0"
      size="0.12 0.0144 0.096"
      type="box"
      mass=".2"
    />
    <body name="slidelink" pos="-0.135 -0.192 0">
      <joint name="slide_cabinet" axis="1 0 0" type="slide" range="0 0.264" />
      <geom
        material="M_slide_metal"
        euler="1.57 0 0"
        pos="-0.1098 -0.036 -0.0684"
        size="0.0114 0.0318 0.0114"
        type="cylinder"
      />
      <geom
        material="M_slide_metal"
        euler="1.57 0 0"
        pos="-0.1098 -0.036 0.0684"
        size="0.0114 0.0318 0.0114"
        type="cylinder"
      />
      <geom
        material="M_slide_metal"
        pos="-0.1098 -0.0738 0"
        size="0.0132 0.0954"
        type="cylinder"
      />
      <geom pos="0 -0.012 0" size="0.135 0.018 0.117" type="box" />

      <geom
        class="slide_collision"
        pos="0 -0.012 0"
        size="0.135 0.018 0.117"
        type="box"
        mass=".2"
      />
      <geom
        class="slide_collision"
        euler="1.57 0 0"
        pos="-0.1098 -0.036 -0.0684"
        size="0.0114 0.0318 0.0114"
        type="cylinder"
        mass=".02"
      />
      <geom
        class="slide_collision"
        euler="1.57 0 0"
        pos="-0.1098 -0.036 0.0684"
        size="0.0114 0.0318 0.0114"
        type="cylinder"
        mass=".02"
      />
      <geom
        class="slide_collision"
        pos="-0.1098 -0.0738 0"
        size="0.0132 0.0954"
        type="cylinder"
        mass=".1"
      />
      <site
        type="sphere"
        name="slide_site"
        pos="-0.1098 -0.0738 0"
        size="0.006"
        group="3"
      />
    </body>
  </body>
</mujocoinclude>
